<?xml version="1.0"?>
<robot xmlns:xacro="http://www.ros.org/wiki/xacro">

    <xacro:macro name="wheel" params="name radius width dx dy mass">

        <link name="${name}_link">
            <collision name="${name}">
                <origin xyz="0 0 0" rpy="${PI/2} 0.0 0.0" />
                <geometry>
                    <cylinder radius="${radius}" length="${width}" />
                </geometry>
            </collision>

            <visual>
                <origin xyz="0.0 0.0 0.0" rpy="${PI/2} 0.0 0.0" />
                <geometry>
                    <cylinder radius="${radius}" length="${width}" />
                </geometry>
                <material name="wheel" />
            </visual>
            <xacro:cylinder_inertia radius="${radius}" length="${width}" mass="${mass}">
                <origin xyz="0.0 0.0 0.0" rpy="${PI/2} 0.0 0.0"/>
            </xacro:cylinder_inertia>
        </link>

        <joint name="${name}_joint" type="continuous">
            <parent link="${robot_name}/base_link" />
            <child link="${name}_link" />
            <origin xyz="${dx} ${dy} ${radius}" rpy="0 0 0" />
            <axis xyz="0 1 0" />
            <dynamics damping="0.01" friction="5" />
        </joint>

        <transmission name="${name}_trans">
            <type>transmission_interface/SimpleTransmission</type>
            <actuator name="${name}_motor">
                <mechanicalReduction>1</mechanicalReduction>
            </actuator>
            <joint name="${name}_joint">
                <hardwareInterface>hardware_interface/VelocityJointInterface</hardwareInterface>
            </joint>
        </transmission>
    </xacro:macro>
</robot>